Workbook
Name \\c: 'FF BOQ 17'!#REF!
Name \\c: 'FF BOQ 18'!#REF!
Name \\c: #N/A
Name \\c: #N/A
Name \\c: #N/A
Name \\c: #N/A
Name \\x: 'FF BOQ 17'!#REF!
Name \\x: 'FF BOQ 18'!#REF!
Name \\x: #N/A
Name \\x: #N/A
Name \\x: #N/A
Name \\x: #N/A
Name \0: #REF!
Name \0: #REF!
Name \0: #REF!
Name \A: #REF!
Name \A: #REF!
Name \A: #REF!
Name \B: #REF!
Name \c: #REF!
Name \d: #REF!
Name \E: #REF!
Name \f: #REF!
Name \g: #REF!
Name \h: #REF!
Name \i: #REF!
Name \j: #REF!
Name \k: #REF!
Name \l: #REF!
Name \M: #REF!
Name \n: #REF!
Name \o: #REF!
Name \p: #REF!
Name \q: #REF!
Name \r: #REF!
Name \s: #REF!
Name \t: #REF!
Name \u: #REF!
Name \v: #REF!
Name \w: #REF!
Name \x: #REF!
Name \y: #REF!
Name \z: #REF!
Name _________COL14: #REF!
Name _________COL16: #REF!
Name _________COL23: #REF!
Name _________COL24: #REF!
Name _________COL25: #REF!
Name _________COL26: #REF!
Name _________COL29: #REF!
Name _________COL6: #REF!
Name _________PCC10: #REF!
Name _________PCC11: #REF!
Name _________PCC12: #REF!
Name _________PCC6: #REF!
Name _________PCC7: #REF!
Name _________PCC8: #REF!
Name _________PCC9: #REF!
Name _______COL10: #REF!
Name _______COL11: #REF!

Sheet Grand Summary
A1: EY Karachi - 17th, & 18th Floors - Grand Summary
A4: S.No | B4: DOMAIN | C4: MATERIAL AMOUNT (Rs.) | D4: INSTALLATION AMOUNT (Rs.) | E4: TOTAL AMOUNT (Rs.)
A6: A | B6: HVAC & Plumbign Works
A7: i | B7: 17th Floor | C7: ='M&P BOQ 17'!I201 -> 24893699 | D7: ='M&P BOQ 17'!K201 -> 3808621.8 | E7: =D7+C7 -> 28702321
A8: ii | B8: 18th Floor | C8: ='M&P BOQ 18'!I201 -> 26014168 | D8: ='M&P BOQ 18'!K201 -> 3431812.8 | E8: =D8+C8 -> 29445980
A10: B | B10: Fire Fighting Works
A11: i | B11: 17th Floor | C11: ='FF BOQ 17'!G65 -> 6343532 | D11: ='FF BOQ 17'!I65 -> 1366574.4 | E11: =D11+C11 -> 7710106.4
A12: ii | B12: 18th Floor | C12: ='FF BOQ 18'!G65 -> 6469436 | D12: ='FF BOQ 18'!I65 -> 1390413.6 | E12: =D12+C12 -> 7859849.6
B14: Total= | C14: =SUM(C5:C12) -> 63720835 | D14: =SUM(D5:D12) -> 9997422.6 | E14: =SUM(E5:E12) -> 73718257

Sheet M&P BOQ 17
A1: BILL OF QUANTITIES
A3: ITEM NO. | B3: DESCRIPTION | E3: VERIFIED QUANTITY | F3: EXTIMATED QUANTITY | G3: UNIT | H3: MATERIAL | J3: INSTALLATION | L3: TOTAL | N3: LEAD TIMES | O3: BRANDS | P3: REMARKS
H4: RATE | I4: AMOUNT | J4: RATE | K4: AMOUNT | L4: RATE | M4: AMOUNT
H5: (Rs.) | I5: (Rs.) | J5: (Rs.) | K5: (Rs.) | L5: (Rs.) | M5: (Rs.)
A6: 1 | B6: FAN COIL UNITS (SECTION 23 73 20 & DS/1909-23 73 20)
A7: 1.1 | B7: Supply & Installation of Fan Coil Units (FCU-17/01) (3.0 TR) Ceiling Hung Type including Wall Mounted Room Thermostat with Scheduling Feature and Auxiliary Drain Pan. | E7: 1 | F7: 1 | G7: No. | H7: 817000 | I7: =H7*E7 -> 817000 | J7: 10320 | K7: =J7*E7 -> 10320 | L7: =J7+H7 -> 827320 | M7: =K7+I7 -> 827320 | N7: Trane | O7: 04 to 05 Months | P7: Awaiting from the supplier
A8: 1.2 | B8: Engineered Supports as per Hitli/Sikla/Walraven/Fischer with Lindapter Type/TR60 complete in all respect | E8: 1 | F8: 1 | G8: Lot | H8: 8600 | I8: =H8*E8 -> 8600 | J8: 1720 | K8: =J8*E8 -> 1720 | L8: =J8+H8 -> 10320 | M8: =K8+I8 -> 10320 | N8: INDEX | O8: 03 to 04 Weeks
A9: 1.3 | B9: Commissioning & Testing | E9: 1 | F9: 1 | G9: No. | I9: =H9*E9 -> 0 | J9: 8600 | K9: =J9*E9 -> 8600 | L9: =J9+H9 -> 8600 | M9: =K9+I9 -> 8600
A10: Sub-total Carried to Summary | J10: 0
A11: 2 | B11: VAV TERMINALS (SECTION 23 36 10 & DS/1909-23 36 10) | J11: 0
A12: 2.1 | B12: Supply & installation of Variable Air Volume (VAV) Terminals with Wall Mounted Thermostat having temperature (Inc./dec.) (Section 23 36 10 & DS/1909-23 36 10) | E12: 21 | F12: 21 | G12: Nos. | H12: 141900 | I12: =H12*E12 -> 2979900 | J12: 8600 | K12: =J12*E12 -> 180600 | L12: =J12+H12 -> 150500 | M12: =K12+I12 -> 3160500 | N12: JES | O12: 02 to 03 Months | P12: Awaiting from the supplier
A13: 2.2 | B13: Engineered Supports system for VAV Terminals with Lindapter Type/TR60 | E13: 1 | F13: 1 | G13: Lot | H13: 25800 | I13: =H13*E13 -> 25800 | J13: 8600 | K13: =J13*E13 -> 8600 | L13: =J13+H13 -> 34400 | M13: =K13+I13 -> 34400
A14: 2.3 | B14: Commissioning & Testing of VAV Terminals | E14: 1 | F14: 1 | G14: Lot | H14: 0 | I14: =H14*E14 -> 0 | J14: 86000 | K14: =J14*E14 -> 86000 | L14: =J14+H14 -> 86000 | M14: =K14+I14 -> 86000
A15: Sub-total Carried to Summary | J15: 0
A16: 3 | B16: DUCT WORK (MACHINE MADE) (SECTION 23 31 13) | J16: 0
A17: 3.1 | B17: Sheet Metal Duct Work (Air Conditioning) (Supply Air), Machine made Ducts (Section 23 31 13) | E17: 13610 | F17: 13220 | G17: Ft² | H17: 425.7 | I17: =H17*E17 -> 5793777 | J17: 86 | K17: =J17*E17 -> 1170460 | L17: =J17+H17 -> 511.7 | M17: =K17+I17 -> 6964237 | N17: ISL | O17: 02 to 03 Weeks
A18: 3.2 | B18: Sheet Metal Duct Work (Air Conditioning) (Return Air), Machine made Ducts (Section 23 31 13) | E18: 180 | F18: 100 | G18: Ft² | H18: 425.7 | I18: =H18*E18 -> 76626 | J18: 86 | K18: =J18*E18 -> 15480 | L18: =J18+H18 -> 511.7 | M18: =K18+I18 -> 92106
A19: 3.3 | B19: Sheet Metal Duct Work (Exhaust Air) Machine made Ducts (Section 23 31 13) | E19: 660 | F19: 600 | G19: Ft² | H19: 425.7 | I19: =H19*E19 -> 280962 | J19: 86 | K19: =J19*E19 -> 56760 | L19: =J19+H19 -> 511.7 | M19: =K19+I19 -> 337722
A20: 3.4 | B20: Quadrant Volume Damper | E20: 260 | F20: 260 | G20: Ft² | H20: 387 | I20: =H20*E20 -> 100620 | J20: 172 | K20: =J20*E20 -> 44720 | L20: =J20+H20 -> 559 | M20: =K20+I20 -> 145340
A21: 3.5 | B21: Flexible Ducts (Section 23 33 46) with Supports, Complete in all Respect | J21: 0
A22: 3.5.1 | B22: Ø 10" (Ø 250mm) | E22: - | G22: Rft | I22: Rate Only | J22: 0 | K22: Rate Only | M22: Rate Only | N22: Flexiva | O22: 06 to 08 Weeks
A23: 3.5.2 | B23: Ø 8" (Ø 200mm) | E23: 60 | F23: 60 | G23: Rft | H23: 602 | I23: =H23*E23 -> 36120 | J23: 258 | K23: =J23*E23 -> 15480 | L23: =J23+H23 -> 860 | M23: =K23+I23 -> 51600
A24: 3.5.3 | B24: Ø 6" (Ø 150mm) | E24: 70 | F24: 70 | G24: Rft | H24: 421.4 | I24: =H24*E24 -> 29498 | J24: 86 | K24: =J24*E24 -> 6020 | L24: =J24+H24 -> 507.4 | M24: =K24+I24 -> 35518
A25: 3.6 | B25: Butterfly Dampers | J25: 0
A26: 3.6.1 | B26: Ø 10" (Ø 250mm) | E26: - | F26: - | G26: No. | H26: 5590 | I26: Rate Only | J26: 860 | K26: Rate Only | M26: Rate Only | N26: Mehran | O26: 06 to 08 Weeks
A27: 3.6.2 | B27: Ø 8" (Ø 200mm) | E27: 28 | F27: 28 | G27: Nos. | H27: 4730 | I27: =H27*E27 -> 132440 | J27: 860 | K27: =J27*E27 -> 24080 | L27: =J27+H27 -> 5590 | M27: =K27+I27 -> 156520
A28: 3.6.3 | B28: Ø 6" (Ø 150mm) | E28: 30 | F28: 30 | G28: Nos. | H28: 4300 | I28: =H28*E28 -> 129000 | J28: 860 | K28: =J28*E28 -> 25800 | L28: =J28+H28 -> 5160 | M28: =K28+I28 -> 154800
A29: 3.7 | B29: Fire Damper - (UL - Listed) | J29: 0
A30: 3.7.1 | B30: 18" x 10" (450mm x 250mm) | E30: 2 | F30: 2 | G30: Nos. | H30: 27520 | I30: =H30*E30 -> 55040 | J30: 2580 | K30: =J30*E30 -> 5160 | L30: =J30+H30 -> 30100 | M30: =K30+I30 -> 60200 | N30: Mehran | O30: 02 to 03 Months
A31: 3.7.2 | B31: 14" x 14" (350mm x 350mm) | E31: 2 | F31: 2 | G31: Nos. | H31: 25800 | I31: =H31*E31 -> 51600 | J31: 2580 | K31: =J31*E31 -> 5160 | L31: =J31+H31 -> 28380 | M31: =K31+I31 -> 56760
A32: 3.8 | B32: Backdraft Damper | J32: 0
A33: 3.8.1 | B33: 44" x 14" (1100mm x 350mm) | E33: 1 | F33: 1 | G33: No. | H33: 16340 | I33: =H33*E33 -> 16340 | J33: 1720 | K33: =J33*E33 -> 1720 | L33: =J33+H33 -> 18060 | M33: =K33+I33 -> 18060 | N33: Mehran | O33: 06 to 08 Weeks
A34: 3.8.2 | B34: 14" x 14" (350mm x 350mm) | E34: 1 | F34: 1 | G34: No. | H34: 6020 | I34: =H34*E34 -> 6020 | J34: 860 | K34: =J34*E34 -> 860 | L34: =J34+H34 -> 6880 | M34: =K34+I34 -> 6880
A35: 3.9 | B35: Cross Talk Silencers for Return Air Intake Size 18" x 8" - Refer FND Detail FND/D/35 | E35: 26 | F35: 26 | G35: Nos. | H35: 7310 | I35: =H35*E35 -> 190060 | J35: 1720 | K35: =J35*E35 -> 44720 | L35: =J35+H35 -> 9030 | M35: =K35+I35 -> 234780
A36: 3.1 | B36: Light Testing for Duct Work | E36: 1 | F36: 1 | G36: Lot | H36: 0 | I36: =H36*E36 -> 0 | J36: 21500 | K36: =J36*E36 -> 21500 | L36: =J36+H36 -> 21500 | M36: =K36+I36 -> 21500
A37: 3.11 | B37: G.I Frame as Duct Sleeves - As per FND Detail | E37: 1 | F37: 1 | G37: Lot | H37: 12900 | I37: =H37*E37 -> 12900 | J37: 6020 | K37: =J37*E37 -> 6020 | L37: =J37+H37 -> 18920 | M37: =K37+I37 -> 18920
A38: 3.12 | B38: Wire Mesh on all Duct Openings | E38: 1 | F38: 1 | G38: Lot | H38: 21500 | I38: =H38*E38 -> 21500 | J38: 4300 | K38: =J38*E38 -> 4300 | L38: =J38+H38 -> 25800 | M38: =K38+I38 -> 25800
A39: 3.13 | B39: Engineered Support system for Ducts with Lindapter Type/TR60 Complete in all Respect | E39: 1 | F39: 1 | G39: Lot | H39: 150500 | I39: =H39*E39 -> 150500 | J39: 21500 | K39: =J39*E39 -> 21500 | L39: =J39+H39 -> 172000 | M39: =K39+I39 -> 172000
A40: Sub-total Carried to Summary
A41: 4 | B41: PIPING (SECTION 23 21 13 & DS/1909-23 21 13)
...

Sheet M&P BOQ 18
A1: BILL OF QUANTITIES
A3: (1) | B3: (2) | E3: (3) | G3: (4) | H3: (5) | I3: (6) | J3: (7) | K3: (8) | L3: (9) | M3: (10)
A4: ITEM NO. | B4: DESCRIPTION | E4: VERIFIED QUANTITY | F4: EXTIMATED QUANTITY | G4: UNIT | H4: MATERIAL | J4: INSTALLATION | L4: TOTAL | N4: LEAD TIMES | O4: BRANDS | P4: REMARKS
H5: RATE | I5: AMOUNT | J5: RATE | K5: AMOUNT | L5: RATE | M5: AMOUNT
H6: (Rs.) | I6: (Rs.) | J6: (Rs.) | K6: (Rs.) | L6: (Rs.) | M6: (Rs.)
A7: 1 | B7: FAN COIL UNITS (SECTION 23 73 20 & DS/1909-23 73 20)
A8: 1.1 | B8: Supply & Installation of Fan Coil Units (FCU-18/01-02) (6.0 TR) Ceiling Hung Type including Wall Mounted Room Thermostat with Scheduling Feature and Auxiliary Drain Pan. | E8: 2 | F8: 2 | G8: Nos. | H8: 731000 | I8: =H8*E8 -> 1462000 | J8: 17200 | K8: =J8*E8 -> 34400 | L8: =J8+H8 -> 748200 | M8: =K8+I8 -> 1496400 | N8: Trane | O8: 04 to 05 Months | P8: Awaiting from the supplier
A9: 1.2 | B9: Engineered Supports as per Hitli/Sikla/Walraven/Fischer with Lindapter Type/TR60 complete in all respect | E9: 1 | F9: 1 | G9: Lot | H9: 8600 | I9: =H9*E9 -> 8600 | J9: 4300 | K9: =J9*E9 -> 4300 | L9: =J9+H9 -> 12900 | M9: =K9+I9 -> 12900 | N9: INDEX | O9: 03 to 04 Weeks
A10: 1.3 | B10: Commissioning & Testing | E10: 2 | F10: 2 | G10: Nos. | H10: 0 | I10: =H10*E10 -> 0 | J10: 8600 | K10: =J10*E10 -> 17200 | L10: =J10+H10 -> 8600 | M10: =K10+I10 -> 17200
A11: Sub-total Carried to Summary | H11: 0 | J11: 0
A12: 2 | B12: VAV TERMINALS (SECTION 23 36 10 & DS/1909-23 36 10) | H12: 0 | J12: 0
A13: 2.1 | B13: Supply & installation of Variable Air Volume (VAV) Terminals with Wall Mounted Thermostat having temperature (Inc./dec.) and CFM indication (Section 23 36 10 & DS/1909-23 36 10) | E13: 12 | F13: 12 | G13: Nos. | H13: 193500 | I13: =H13*E13 -> 2322000 | J13: 4128 | K13: =J13*E13 -> 49536 | L13: =J13+H13 -> 197628 | M13: =K13+I13 -> 2371536 | N13: JES | O13: 02 to 03 Months | P13: Awaiting from the supplier
A14: 2.2 | B14: Engineered Supports system for VAV Terminals with Lindapter Type/TR60 | E14: 1 | F14: 1 | G14: Lot | H14: 21500 | I14: =H14*E14 -> 21500 | J14: 4300 | K14: =J14*E14 -> 4300 | L14: =J14+H14 -> 25800 | M14: =K14+I14 -> 25800
A15: 2.3 | B15: Commissioning & Testing of VAV Terminals | E15: 1 | F15: 1 | G15: Lot | H15: 0 | I15: =H15*E15 -> 0 | J15: 43000 | K15: =J15*E15 -> 43000 | L15: =J15+H15 -> 43000 | M15: =K15+I15 -> 43000
A16: Sub-total Carried to Summary | H16: 0 | J16: 0
A17: 3 | B17: DUCT WORK (MACHINE MADE) (SECTION 23 31 13) | H17: 0 | J17: 0
A18: 3.1 | B18: Sheet Metal Duct Work (Air Conditioning) (Supply Air), Machine made Ducts (Section 23 31 13) | E18: 11360 | F18: 10900 | G18: Ft² | H18: 425.7 | I18: =H18*E18 -> 4835952 | J18: 86 | K18: =J18*E18 -> 976960 | L18: =J18+H18 -> 511.7 | M18: =K18+I18 -> 5812912 | N18: ISL | O18: 02 to 03 Weeks
A19: 3.2 | B19: Sheet Metal Duct Work (Air Conditioning) (Return Air), Machine made Ducts (Section 23 31 13) | E19: 220 | F19: 200 | G19: Ft² | H19: 425.7 | I19: =H19*E19 -> 93654 | J19: 86 | K19: =J19*E19 -> 18920 | L19: =J19+H19 -> 511.7 | M19: =K19+I19 -> 112574
A20: 3.3 | B20: Sheet Metal Duct Work (Exhaust Air) Machine made Ducts (Section 23 31 13) | E20: 640 | F20: 600 | G20: Ft² | H20: 425.7 | I20: =H20*E20 -> 272448 | J20: 86 | K20: =J20*E20 -> 55040 | L20: =J20+H20 -> 511.7 | M20: =K20+I20 -> 327488
A21: 3.4 | B21: Quadrant Volume Damper | E21: 160 | F21: 160 | G21: Ft² | H21: 387 | I21: =H21*E21 -> 61920 | J21: 172 | K21: =J21*E21 -> 27520 | L21: =J21+H21 -> 559 | M21: =K21+I21 -> 89440
A22: 3.5 | B22: Flexible Ducts (Section 23 33 46) with Supports, Complete in all respect | H22: 0 | J22: 0
A23: 3.5.1 | B23: Ø 10" (Ø 250mm) | E23: - | F23: - | G23: Rft | H23: 0 | I23: Rate Only | J23: 0 | K23: Rate Only | M23: Rate Only | N23: Flexiva | O23: 06 to 08 Weeks
A24: 3.5.2 | B24: Ø 8" (Ø 200mm) | E24: - | F24: - | G24: Rft | H24: 0 | I24: Rate Only | J24: 0 | K24: Rate Only | M24: Rate Only
A25: 3.5.3 | B25: Ø 6" (Ø 150mm) | E25: 96 | F25: 96 | G25: Rft | H25: 421.4 | I25: =H25*E25 -> 40454.4 | J25: 86 | K25: =J25*E25 -> 8256 | L25: =J25+H25 -> 507.4 | M25: =K25+I25 -> 48710.4
A26: 3.6 | B26: Butterfly Dampers | H26: 0 | J26: 0
A27: 3.6.1 | B27: Ø 10" (Ø 250mm) | E27: - | F27: - | G27: No. | H27: 6450 | I27: Rate Only | J27: 860 | K27: Rate Only | M27: Rate Only | N27: Mehran | O27: 06 to 08 Weeks
A28: 3.6.2 | B28: Ø 8" (Ø 200mm) | E28: - | F28: - | G28: No. | H28: 4730 | I28: Rate Only | J28: 860 | K28: Rate Only | M28: Rate Only
A29: 3.6.3 | B29: Ø 6" (Ø 150mm) | E29: 48 | F29: 48 | G29: Nos. | H29: 4472 | I29: =H29*E29 -> 214656 | J29: 860 | K29: =J29*E29 -> 41280 | L29: =J29+H29 -> 5332 | M29: =K29+I29 -> 255936
A30: 3.7 | B30: Fire Damper - (UL - Listed) | H30: 0 | J30: 0
A31: 3.7.1 | B31: 20" x 16" (500mm x 400mm) | E31: 2 | F31: 2 | G31: Nos. | H31: 30100 | I31: =H31*E31 -> 60200 | J31: 2580 | K31: =J31*E31 -> 5160 | L31: =J31+H31 -> 32680 | M31: =K31+I31 -> 65360 | N31: Mehran | O31: 02 to 03 Months
A32: 3.7.2 | B32: 18" x 10" (450mm x 250mm) | E32: 2 | F32: 2 | G32: Nos. | H32: 27520 | I32: =H32*E32 -> 55040 | J32: 2580 | K32: =J32*E32 -> 5160 | L32: =J32+H32 -> 30100 | M32: =K32+I32 -> 60200
A33: 3.8 | B33: Backdraft Damper | H33: 0 | J33: 0
A34: 3.8.1 | B34: 44" x 14" (1100mm x 350mm) | E34: 2 | F34: 2 | G34: Nos. | H34: 16340 | I34: =H34*E34 -> 32680 | J34: 1720 | K34: =J34*E34 -> 3440 | L34: =J34+H34 -> 18060 | M34: =K34+I34 -> 36120 | N34: Mehran | O34: 06 to 08 Weeks
A35: 3.8.2 | B35: 14" x 14" (350mm x 350mm) | E35: 2 | F35: 2 | G35: Nos. | H35: 6020 | I35: =H35*E35 -> 12040 | J35: 860 | K35: =J35*E35 -> 1720 | L35: =J35+H35 -> 6880 | M35: =K35+I35 -> 13760
A36: 3.9 | B36: Cross Talk Silencers for Return Air Intake Size 18" x 8" - Refer FND Detail FND/D/35 | E36: 14 | F36: 14 | G36: Nos. | H36: 7310 | I36: =H36*E36 -> 102340 | J36: 1720 | K36: =J36*E36 -> 24080 | L36: =J36+H36 -> 9030 | M36: =K36+I36 -> 126420
A37: 3.1 | B37: Light Testing for Duct Work | E37: 1 | F37: 1 | G37: Lot | H37: 0 | I37: =H37*E37 -> 0 | J37: 21500 | K37: =J37*E37 -> 21500 | L37: =J37+H37 -> 21500 | M37: =K37+I37 -> 21500
A38: 3.11 | B38: G.I Frame as Duct Sleeves - As per FND Detail | E38: 1 | F38: 1 | G38: Lot | H38: 12900 | I38: =H38*E38 -> 12900 | J38: 6020 | K38: =J38*E38 -> 6020 | L38: =J38+H38 -> 18920 | M38: =K38+I38 -> 18920
A39: 3.12 | B39: Wire Mesh on all Duct Openings | E39: 1 | F39: 1 | G39: Lot | H39: 21500 | I39: =H39*E39 -> 21500 | J39: 4300 | K39: =J39*E39 -> 4300 | L39: =J39+H39 -> 25800 | M39: =K39+I39 -> 25800
A40: 3.13 | B40: Engineered Support system for Ducts with Lindapter Type/TR60 Complete in all Respect | E40: 1 | F40: 1 | G40: Lot | H40: 150500 | I40: =H40*E40 -> 150500 | J40: 21500 | K40: =J40*E40 -> 21500 | L40: =J40+H40 -> 172000 | M40: =K40+I40 -> 172000
A41: Sub-total Carried to Summary | J41: 0
...

Sheet FF BOQ 17
A1: BILL OF QUANTITIES
A3: ITEM NO. | B3: DESCRIPTION | C3: VERIFIED QUANTITY | D3: EXTIMATED QUANTITY | E3: UNIT | F3: INSTALLATION | H3: TOTAL | J3: TOTAL | L3: LEAD TIMES | M3: BRANDS | N3: REMARKS
F4: RATE | G4: AMOUNT | H4: RATE | I4: AMOUNT | J4: RATE | K4: AMOUNT
F5: (Rs.) | G5: (Rs.) | H5: (Rs.) | I5: (Rs.) | J5: (Rs.) | K5: (Rs.)
A6: 1 | B6: FIRE SPRINKLERS (SECTION 21 13 10 & DS/1909-21 13 10)
A7: 1.1 | B7: Fire Sprinkler- Upright, Quick Response (SP-01) | C7: 83 | D7: 83 | E7: Nos. | F7: 2752 | G7: =F7*C7 -> 228416 | H7: 860 | I7: =H7*C7 -> 71380 | J7: =H7+F7 -> 3612 | K7: =I7+G7 -> 299796 | L7: SHIELD | M7: 02 to 03 Months
A8: 1.2 | B8: Fire Sprinkler- Pendent Concealed, Quick Response (SP-02) | C8: 195 | D8: 195 | E8: Nos. | F8: 2150 | G8: =F8*C8 -> 419250 | H8: 860 | I8: =H8*C8 -> 167700 | J8: =H8+F8 -> 3010 | K8: =I8+G8 -> 586950
A9: 1.3 | B9: Fire Sprinkler- Pendent Sprinkler, Quick Response (SP-03) | C9: 25 | D9: 25 | E9: Nos. | F9: 3612 | G9: =F9*C9 -> 90300 | H9: 860 | I9: =H9*C9 -> 21500 | J9: =H9+F9 -> 4472 | K9: =I9+G9 -> 111800
A10: 1.4 | B10: Cabinet Complete with 06 Spare Sprinklers (Upright) (SP-01) | C10: 1 | D10: 1 | E10: Nos. | F10: 66220 | G10: =F10*C10 -> 66220 | H10: 1720 | I10: =H10*C10 -> 1720 | J10: =H10+F10 -> 67940 | K10: =I10+G10 -> 67940
A11: 1.5 | B11: Cabinet Complete with 06 Spare Sprinklers (Concealed Pendent) (SP-02) | C11: 1 | D11: 1 | E11: No. | F11: 66220 | G11: =F11*C11 -> 66220 | H11: 1720 | I11: =H11*C11 -> 1720 | J11: =H11+F11 -> 67940 | K11: =I11+G11 -> 67940
A12: 1.6 | B12: Cabinet Complete with 06 Spare Sprinklers (Pendent) (SP-03) | C12: 1 | D12: 1 | E12: No. | F12: 41280 | G12: =F12*C12 -> 41280 | H12: 1720 | I12: =H12*C12 -> 1720 | J12: =H12+F12 -> 43000 | K12: =I12+G12 -> 43000
A13: Sub-total Carried to Summary | F13: 0 | H13: 0
A14: 2 | B14: CORRUGATED STAINLESS STEEL FLEXIBLE CONNECTOR | F14: 0 | H14: 0
A15: 2.1 | B15: Corrugated Stainless Steel Flexible Connector Ø 1" X 3 ft (UL/FM) (Braided) | C15: =C8 -> 195 | D15: 195 | E15: Nos. | F15: 9374 | G15: =F15*C15 -> 1827930 | H15: 860 | I15: =H15*C15 -> 167700 | J15: =H15+F15 -> 10234 | K15: =I15+G15 -> 1995630 | L15: Seung Jin Ind Co. Ltd. | M15: 02 to 03 Months
A16: Sub-total Carried to Summary | F16: 0 | H16: 0
A17: 3 | B17: PORTABLE FIRE EXTINGUISHER FOR FIRE TYPES A, B, C & AFFF (SECTION 21 21 10 & DS/1909-21 21 10) | F17: 0 | H17: 0
A18: 3.1 | B18: Supply & Installation of 6 Kg Dry Powder Extinguisher (ABC) | C18: 4 | D18: 4 | E18: Nos. | F18: 16340 | G18: =F18*C18 -> 65360 | H18: 860 | I18: =H18*C18 -> 3440 | J18: =H18+F18 -> 17200 | K18: =I18+G18 -> 68800 | L18: NAFFCO | M18: 02 to 03 Months
A19: 3.2 | B19: Supply & Installation of 6 Kg CO2 Fire Extinguisher | C19: 4 | D19: 4 | E19: Nos. | F19: 25370 | G19: =F19*C19 -> 101480 | H19: 860 | I19: =H19*C19 -> 3440 | J19: =H19+F19 -> 26230 | K19: =I19+G19 -> 104920
A20: Sub-total Carried to Summary | F20: 0
A21: 4 | B21: BLACK STEEL SCHEDULE-40 PIPING (SECTION 21 10 10) | F21: 0
A22: 4.1 | B22: Welded Piping System | F22: 0
A23: 4.1.1 | B23: Ø 4" (100mm) | C23: - | E23: Rft | F23: 0 | G23: Rate Only | I23: Rate Only | J23: Rate Only | K23: Rate Only | L23: IIL | M23: 04 to 05 Weeks | N23: IIL Brand is in LOAM
A24: 4.1.2 | B24: Ø 3" (75mm) | C24: 320 | D24: 290 | E24: Rft | F24: 1634 | G24: =F24*C24 -> 522880 | H24: 258 | I24: =H24*C24 -> 82560 | J24: =H24+F24 -> 1892 | K24: =I24+G24 -> 605440
A25: 4.1.3 | B25: Ø 2½" (65mm) | C25: - | D25: - | E25: Rft | F25: 1548 | G25: Rate Only | H25: 172 | I25: Rate Only | J25: Rate Only | K25: Rate Only
A26: 4.2 | B26: Threaded Piping System | F26: 0 | H26: 0
A27: 4.2.1 | B27: Ø 2" (50mm) | C27: 220 | D27: 215 | E27: Rft | F27: 1075 | G27: =F27*C27 -> 236500 | H27: 215 | I27: =H27*C27 -> 47300 | J27: =H27+F27 -> 1290 | K27: =I27+G27 -> 283800
A28: 4.2.2 | B28: Ø 1½" (40mm) | C28: 462 | D28: 455 | E28: Rft | F28: 817 | G28: =F28*C28 -> 377454 | H28: 189.2 | I28: =H28*C28 -> 87410.4 | J28: =H28+F28 -> 1006.2 | K28: =I28+G28 -> 464864.4
A29: 4.2.3 | B29: Ø 1¼" (32mm) | C29: 480 | D29: 400 | E29: Rft | F29: 688 | G29: =F29*C29 -> 330240 | H29: 189.2 | I29: =H29*C29 -> 90816 | J29: =H29+F29 -> 877.2 | K29: =I29+G29 -> 421056
A30: 4.2.4 | B30: Ø 1" (25mm) | C30: 1840 | D30: 1785 | E30: Rft | F30: 584.8 | G30: =F30*C30 -> 1076032 | H30: 189.2 | I30: =H30*C30 -> 348128 | J30: =H30+F30 -> 774 | K30: =I30+G30 -> 1424160
A31: Sub-total Carried to Summary | F31: 0
A32: 5 | B32: GATE VALVE (SECTION 21 05 23) | F32: 0
A33: 5.1 | B33: Ø2 inch (50mm) | C33: 2 | D33: 2 | E33: Nos. | F33: 76540 | G33: Rate Only | H33: 2580 | I33: Rate Only | J33: Rate Only | K33: Rate Only | L33: SHIELD | M33: 04 to 05 Weeks
A34: Sub-total Carried to Summary | F34: 0
A35: 6 | B35: SIESMIC BRACING | F35: 0
A36: 6.1 | B36: Transverse Seismic Bracing (As per FND Detail No. FND/SS/10) | F36: 0
A37: 6.1.1 | B37: Ø 4" (100mm) | C37: - | E37: No. | F37: 0 | G37: Rate Only | I37: Rate Only | J37: Rate Only | K37: Rate Only | L37: INDEX | M37: 04 to 05 Weeks
A38: 6.1.2 | B38: Ø 3" (75mm) | C38: 11 | D38: 11 | E38: Nos. | F38: 7740 | G38: =F38*C38 -> 85140 | H38: 860 | I38: =H38*C38 -> 9460 | J38: =H38+F38 -> 8600 | K38: =I38+G38 -> 94600
A39: 6.1.3 | B39: Ø 2½" (65mm) | C39: - | E39: No. | F39: 0 | G39: Rate Only | I39: Rate Only | J39: Rate Only | K39: Rate Only
A40: 6.2 | B40: Longitudinal Seismic Bracing (As per FND Detail No. FND/SS/11) | F40: 0
A41: 6.2.1 | B41: Ø 4" (100mm) | C41: - | E41: No. | F41: 0 | G41: Rate Only | H41: Rate Only | I41: Rate Only | J41: Rate Only | K41: Rate Only
...

Sheet FF BOQ 18
A1: BILL OF QUANTITIES
A3: ITEM NO. | B3: DESCRIPTION | C3: VERIFIED QUANTITY | D3: EXTIMATED QUANTITY | E3: UNIT | F3: MATERIAL | H3: INSTALLATION | J3: TOTAL | L3: LEAD TIMES | M3: BRANDS | N3: REMARKS
F4: RATE | G4: AMOUNT | H4: RATE | I4: AMOUNT | J4: RATE | K4: AMOUNT
F5: (Rs.) | G5: (Rs.) | H5: (Rs.) | I5: (Rs.) | J5: (Rs.) | K5: (Rs.)
A6: 1 | B6: FIRE SPRINKLERS (SECTION 21 13 10 & DS/1909-21 13 10)
A7: 1.1 | B7: Fire Sprinkler- Upright, Quick Response (SP-01) | C7: 95 | D7: 95 | E7: Nos. | F7: 2752 | G7: =F7*C7 -> 261440 | H7: 860 | I7: =H7*C7 -> 81700 | J7: =H7+F7 -> 3612 | K7: =I7+G7 -> 343140 | L7: SHIELD | M7: 02 to 03 Months
A8: 1.2 | B8: Fire Sprinkler- Pendent Concealed, Quick Response (SP-02) | C8: 200 | D8: 200 | E8: Nos. | F8: 2150 | G8: =F8*C8 -> 430000 | H8: 860 | I8: =H8*C8 -> 172000 | J8: =H8+F8 -> 3010 | K8: =I8+G8 -> 602000
A9: 1.3 | B9: Fire Sprinkler- Pendent Sprinkler, Quick Response (SP-03) | C9: 23 | D9: 23 | E9: Nos. | F9: 3612 | G9: =F9*C9 -> 83076 | H9: 860 | I9: =H9*C9 -> 19780 | J9: =H9+F9 -> 4472 | K9: =I9+G9 -> 102856
A10: 1.4 | B10: Cabinet Complete with 06 Spare Sprinklers (Upright) (SP-01) | C10: 1 | D10: 1 | E10: Nos. | F10: 66220 | G10: =F10*C10 -> 66220 | H10: 1720 | I10: =H10*C10 -> 1720 | J10: =H10+F10 -> 67940 | K10: =I10+G10 -> 67940
A11: 1.5 | B11: Cabinet Complete with 06 Spare Sprinklers (Concealed Pendent) (SP-02) | C11: 1 | D11: 1 | E11: No. | F11: 66220 | G11: =F11*C11 -> 66220 | H11: 1720 | I11: =H11*C11 -> 1720 | J11: =H11+F11 -> 67940 | K11: =I11+G11 -> 67940
A12: 1.6 | B12: Cabinet Complete with 06 Spare Sprinklers (Pendent) (SP-03) | C12: 1 | D12: 1 | E12: No. | F12: 41280 | G12: =F12*C12 -> 41280 | H12: 1720 | I12: =H12*C12 -> 1720 | J12: =H12+F12 -> 43000 | K12: =I12+G12 -> 43000
A13: Sub-total Carried to Summary | F13: 0 | H13: 0
A14: 2 | B14: CORRUGATED STAINLESS STEEL FLEXIBLE CONNECTOR | F14: 0 | H14: 0
A15: 2.1 | B15: Corrugated Stainless Steel Flexible Connector Ø 1" X 3 ft (UL/FM) (Braided) | C15: =C8 -> 200 | D15: 200 | E15: Nos. | F15: 9374 | G15: =F15*C15 -> 1874800 | H15: 860 | I15: =H15*C15 -> 172000 | J15: =H15+F15 -> 10234 | K15: =I15+G15 -> 2046800 | L15: Seung Jin Ind Co. Ltd. | M15: 02 to 03 Months
A16: Sub-total Carried to Summary | F16: 0 | H16: 0
A17: 3 | B17: PORTABLE FIRE EXTINGUISHER FOR FIRE TYPES A, B, C & AFFF (SECTION 21 21 10 & DS/1909-21 21 10) | F17: 0 | H17: 0
A18: 3.1 | B18: Supply & Installation of 6 Kg Dry Powder Extinguisher (ABC) | C18: 4 | D18: 4 | E18: Nos. | F18: 16340 | G18: =F18*C18 -> 65360 | H18: 860 | I18: =H18*C18 -> 3440 | J18: =H18+F18 -> 17200 | K18: =I18+G18 -> 68800 | L18: NAFFCO | M18: 02 to 03 Months
A19: 3.2 | B19: Supply & Installation of 6 Kg CO2 Fire Extinguisher | C19: 4 | D19: 4 | E19: Nos. | F19: 25370 | G19: =F19*C19 -> 101480 | H19: 860 | I19: =H19*C19 -> 3440 | J19: =H19+F19 -> 26230 | K19: =I19+G19 -> 104920
A20: Sub-total Carried to Summary | F20: 0 | H20: 0
A21: 4 | B21: BLACK STEEL SCHEDULE-40 PIPING (SECTION 21 10 10) | F21: 0 | H21: 0
A22: 4.1 | B22: Welded Piping System | F22: 0 | H22: 0
A23: 4.1.1 | B23: Ø 4" (100mm) | C23: - | D23: - | E23: Rft | F23: 0 | G23: Rate Only | H23: 0 | I23: Rate Only | J23: Rate Only | K23: Rate Only | L23: IIL | M23: 04 to 05 Weeks | N23: IIL Brand is in LOAM
A24: 4.1.2 | B24: Ø 3" (75mm) | C24: 332 | D24: 290 | E24: Rft | F24: 1634 | G24: =F24*C24 -> 542488 | H24: 258 | I24: =H24*C24 -> 85656 | J24: =H24+F24 -> 1892 | K24: =I24+G24 -> 628144
A25: 4.1.3 | B25: Ø 2½" (65mm) | C25: - | D25: - | E25: Rft | F25: 1548 | G25: Rate Only | H25: 172 | I25: Rate Only | J25: Rate Only | K25: Rate Only
A26: 4.2 | B26: Threaded Piping System | F26: 0 | H26: 0
A27: 4.2.1 | B27: Ø 2" (50mm) | C27: 240 | D27: 215 | E27: Rft | F27: 1075 | G27: =F27*C27 -> 258000 | H27: 215 | I27: =H27*C27 -> 51600 | J27: =H27+F27 -> 1290 | K27: =I27+G27 -> 309600
A28: 4.2.2 | B28: Ø 1½" (40mm) | C28: 510 | D28: 455 | E28: Rft | F28: 817 | G28: =F28*C28 -> 416670 | H28: 189.2 | I28: =H28*C28 -> 96492 | J28: =H28+F28 -> 1006.2 | K28: =I28+G28 -> 513162
A29: 4.2.3 | B29: Ø 1¼" (32mm) | C29: 408 | D29: 400 | E29: Rft | F29: 688 | G29: =F29*C29 -> 280704 | H29: 189.2 | I29: =H29*C29 -> 77193.6 | J29: =H29+F29 -> 877.2 | K29: =I29+G29 -> 357897.6
A30: 4.2.4 | B30: Ø 1" (25mm) | C30: 1860 | D30: 1785 | E30: Rft | F30: 584.8 | G30: =F30*C30 -> 1087728 | H30: 189.2 | I30: =H30*C30 -> 351912 | J30: =H30+F30 -> 774 | K30: =I30+G30 -> 1439640
A31: Sub-total Carried to Summary | F31: 0 | H31: 0
A32: 5 | B32: GATE VALVE (SECTION 21 05 23) | F32: 0 | H32: 0
A33: 5.1 | B33: Ø2 inch (50 mm) | C33: 2 | D33: 2 | E33: Nos. | F33: 76540 | G33: Rate Only | H33: 2580 | I33: Rate Only | J33: Rate Only | K33: Rate Only | L33: SHIELD | M33: 04 to 05 Weeks
A34: Sub-total Carried to Summary | F34: 0 | H34: 0
A35: 6 | B35: SIESMIC BRACING | F35: 0 | H35: 0
A36: 6.1 | B36: Transverse Seismic Bracing (As per FND Detail No. FND/SS/10) | F36: 0 | H36: 0
A37: 6.1.1 | B37: Ø 4" (100mm) | C37: - | E37: No. | F37: 0 | G37: Rate Only | H37: 0 | I37: Rate Only | J37: Rate Only | K37: Rate Only | L37: INDEX | M37: 04 to 05 Weeks
A38: 6.1.2 | B38: Ø 3" (75mm) | C38: 11 | D38: 11 | E38: Nos. | F38: 7740 | G38: =F38*C38 -> 85140 | H38: 860 | I38: =H38*C38 -> 9460 | J38: =H38+F38 -> 8600 | K38: =I38+G38 -> 94600
A39: 6.1.3 | B39: Ø 2½" (65mm) | C39: - | E39: No. | F39: 0 | G39: Rate Only | H39: 0 | I39: Rate Only | J39: Rate Only | K39: Rate Only
A40: 6.2 | B40: Longitudinal Seismic Bracing (As per FND Detail No. FND/SS/11) | F40: 0 | H40: 0
A41: 6.2.1 | B41: Ø 4" (100mm) | C41: - | E41: No. | F41: 0 | G41: Rate Only | H41: 0 | I41: Rate Only | J41: Rate Only | K41: Rate Only
...

Sheet TOWER-(A) BOQ (2)
A1: TOWER -A&B AT DOLMEN CITY, KARACHI | L1: BILL OF QUANTITIES
A2: TOWER 'A' - HVAC SYSTEM WORKS | L2: DATED: JANUARY 10, 2017
A4: BILL OF QUANTITIES - TOWER 'A'
A6: (1) | B6: (2) | E6: (3) | F6: (4) | G6: (5) | H6: (6) | I6: (7) | J6: (8) | K6: (9) | L6: (10)
A7: ITEM NO. | B7: DESCRIPTION | E7: ESTIMATED QUANTITY | F7: UNIT | G7: MATERIAL | I7: INSTALLATION | K7: TOTAL
G8: RATE | H8: AMOUNT | I8: RATE | J8: AMOUNT | K8: RATE | L8: AMOUNT
G9: (Rs.) | H9: (Rs.) | I9: (Rs.) | J9: (Rs.) | K9: (Rs.) | L9: (Rs.)
H10: (3) x (5) | J10: (3) x (7) | K10: (5) + (7) | L10: (6) + (8)
A11: 1 | B11: INSTALLATION OF AIR HANDLING UNITS {OWNER FURNISHED} (SECTION 23 73 10 & DS/1283-23 73 10) | N11: INSTALLATION OF AIR HANDLING UNITS {OWNER FURNISHED} (SECTION 23 73 10 & DS/1283-23 73 10)
A12: 1.1 | B12: Installation of Air Handling Units - Ceiling Hung (Type-A) | E12: 186 | F12: Nos. | Q12: 18 | R12: No
A13: 1.2 | B13: Installation of Air Handling Units - Ceiling Hung (Type-B) | E13: 4 | F13: Nos. | Q13: 68 | R13: No
A14: 1.3 | B14: Installation of Air Handling Units - Ceiling Hung (Type-C) | E14: 45 | F14: Nos. | Q14: 74 | R14: No
A15: 1.4 | B15: Installation of Air Handling Units - Ceiling Hung (Type-D) | E15: 29 | F15: Nos. | Q15: 10 | R15: No
A16: 1.5 | B16: Installation of Air Handling Units - Floor Mounted (AHU/TA-ENT-01) | E16: 1 | F16: Nos. | N16: Installation of Air Handling Units - Floor Mounted (158TR) | Q16: 2 | R16: No
A17: 1.6 | B17: Installation of Air Handling Units - Floor Mounted (AHU/CHWPR-TA-01 & 02) | E17: 2 | F17: Nos. | N17: Installation of Air Handling Units - Floor Mounted (101TR) | Q17: 2 | R17: No
A18: 1.7 | B18: Installation of Air Handling Units - Floor Mounted (AHU/TA-MCC) | E18: 1 | F18: Nos. | N18: Installation of Air Handling Units - Floor Mounted (122TR) | Q18: 2 | R18: No
A19: 1.8 | B19: Installation of Air Handling Units - Floor Mounted (FAAHU/TA-01) | E19: 2 | F19: Nos. | N19: Installation of Air Handling Units - Floor Mounted (122TR) | Q19: 2 | R19: No
A20: 1.9 | B20: Installation of Air Handling Units - Floor Mounted (FAAHU/TA-02) | E20: 2 | F20: Nos. | N20: Installation of Air Handling Units - Floor Mounted (122TR) | Q20: 2 | R20: No
A21: 1.1 | B21: Lifting & Shifting of Equipments to the Location Designated for Installation | E21: 1 | F21: Lot | N21: Installation of Air Handling Units - Floor Mounted (48TR) | Q21: 1 | R21: No
A22: 1.11 | B22: Foundation {Refer Detail # FND/D/ADD05B} / Supports (Hot Dipped Galvanized Upto 50 to 70 Micron) of Ceiling Hung AHUs | E22: 1 | F22: Lot | N22: Installation of Air Handling Units - Floor Mounted (44TR) | Q22: 1 | R22: No
A23: 1.12 | B23: Foundation {Refer Detail -Type C} / Supports of Floor Mounted AHUs | E23: 1 | F23: Lot | N23: Installation of Air Handling Units - Floor Mounted (23TR) | Q23: 2 | R23: No
A24: 1.13 | B24: Commissioning & Testing | E24: 1 | F24: Lot | N24: Installation of Air Handling Units - Floor Mounted (36TR) | Q24: 1 | R24: No
A25: 1.14 | B25: Ø ½" (Ø 15mm) Shrader Fitting (Pressure Class 300/ PN 20) For Air Vent/Pressure Testing | E25: 382 | F25: Nos.
A26: 1.15 | B26: Ø ½" (Ø 15mm) Shrader Fitting For Air Vent/Pressure Testing | E26: 146 | F26: Nos.
A27: Sub-total Carried to Summary | N27: Lifting & Shifting of Equipments to the Location Designated for Installation | Q27: 181 | R27: Nos.
A28: 2 | B28: INSTALLATION OF ROTARY H.E. AIR TO AIR {OWNER FURNISHED} (SECTION 23 72 13 & DS/1283-23 72 13) | N28: Foundation / Supports (Hot Dipped Galvanized) for Ceiling Hung AHUs | Q28: 1 | R28: Lot
A29: 2.1 | B29: Installation of Heat Recovery Units (HRU/TA-01) | E29: 2 | F29: Nos. | N29: Foundation / Supports (Hot Dipped Galvanized) for Floor Mounted AHUs | Q29: 1 | R29: Lot
A30: 2.2 | B30: Installation of Heat Recovery Units (HRU/TA-02) | E30: 2 | F30: Nos. | N30: Commissioning & Testing | Q30: 1 | R30: Lot
A31: 2.3 | B31: Lifting & Shifting of Equipments to the Location Designated for Installation | E31: 1 | F31: Lot
A32: 2.4 | B32: Foundation & Supports (Hot Dipped Galvanized Upto 50 to 70 Micron) | E32: 1 | F32: Lot
A33: 2.5 | B33: Commissioning & Testing | E33: 1 | F33: Lot
A34: Sub-total Carried to Summary
A35: 3 | B35: HEAT EXCHANGER (SECTION 23 57 10 & DS/1283-23 57 10)
A36: 3.1 | B36: Supply and Installation of Plate Type Heat Exchanger on Chilled Water (HX/TA-01 to 03) | E36: 3 | F36: Nos.
A37: 3.2 | B37: Supply and Installation of Plate Type Heat Exchanger on 24Hrs Cooling Water (HX/TA-04 & 05) | E37: 2 | F37: Nos.
A38: 3.3 | B38: Lifting & Shifting of Equipment to the Location Designated for Installation | E38: 1 | F38: Lot
A39: 3.4 | B39: Foundation / Supports (Hot Dipped Galvanized Upto 50 to 70 Micron) | E39: 1 | F39: Lot
A40: 3.5 | B40: Commissioning & Testing | E40: 1 | F40: Lot
A41: Sub-total Carried to Summary
A42: 4 | B42: INSTALLATION OF FILTER SECTION WITH EMPTY SECTIONS {OWNER FURNISHED} (SECTION 23 41 10 & DS/1283-23 41 10)
...
