Workbook
Name \\c: Fire!#REF!
Name \\c: HVAC!#REF!
Name \\c: Plumbing!#REF!
Name \\c: SUMM!#REF!
Name \\c: #REF!
Name \\x: Fire!#REF!
Name \\x: HVAC!#REF!
Name \\x: Plumbing!#REF!
Name \\x: SUMM!#REF!
Name \\x: #REF!
Name \\xx: #REF!
Name \\xx: #REF!
Name \\xx: #REF!
Name \d: '[1]6.1-TRI'!#REF!
Name \d: '[1]6.1-TRI'!#REF!
Name \d: '[1]6.1-TRI'!#REF!
Name \e: '[1]6.1-TRI'!#REF!
Name \e: '[1]6.1-TRI'!#REF!
Name \e: '[1]6.1-TRI'!#REF!
Name \i: '[1]6.1-TRI'!#REF!
Name \i: '[1]6.1-TRI'!#REF!
Name \i: '[1]6.1-TRI'!#REF!
Name \m: '[1]6.1-TRI'!#REF!
Name \m: '[1]6.1-TRI'!#REF!
Name \m: '[1]6.1-TRI'!#REF!
Name \X: '[2]URA-C1'!#REF!
Name \X: '[2]URA-C1'!#REF!
Name \X: '[2]URA-C1'!#REF!
Name \z: '[3]URA-C1'!#REF!
Name \z: '[3]URA-C1'!#REF!
Name \z: '[3]URA-C1'!#REF!
Name _____________________________________MS16: #REF!
Name _____________________________________MS16: #REF!
Name _____________________________________MS16: #REF!
Name _____________________________________MS6: #REF!
Name _____________________________________MS6: #REF!
Name _____________________________________MS6: #REF!
Name ____________________________________MS16: #REF!
Name ____________________________________MS16: #REF!
Name ____________________________________MS16: #REF!
Name ____________________________________MS6: #REF!
Name ____________________________________MS6: #REF!
Name ____________________________________MS6: #REF!
Name ___________________________________MS16: #REF!
Name ___________________________________MS16: #REF!
Name ___________________________________MS16: #REF!
Name ___________________________________MS6: #REF!
Name ___________________________________MS6: #REF!
Name ___________________________________MS6: #REF!
Name __________________________________MS16: #REF!
Name __________________________________MS16: #REF!
Name __________________________________MS16: #REF!
Name __________________________________MS6: #REF!
Name __________________________________MS6: #REF!
Name __________________________________MS6: #REF!
Name _________________________________MS16: #REF!
Name _________________________________MS16: #REF!
Name _________________________________MS16: #REF!
Name _________________________________MS6: #REF!
Name _________________________________MS6: #REF!

Sheet SUMM
A1: DOLMEN CITY FAMILY AREA, SECOND FLOOR
A4: S.NO | B4: SUMMARY OF COST | C4: Material | D4: Labour | E4: Total Amount
A6: 1 | B6: HVAC | C6: =HVAC!H88 -> 1659649.5 | D6: =HVAC!J88 -> 639360 | E6: =D6+C6 -> 2299009.5
A8: 2 | B8: Fire Fighting | C8: =Fire!F90 -> 500600 | D8: =Fire!H90 -> 198000 | E8: =D8+C8 -> 698600
A10: 3 | B10: Plumbing | C10: =Plumbing!G97 -> 2909406 | D10: =Plumbing!I97 -> 428800 | E10: =D10+C10 -> 3338206
B11: Discount on Plumbing | E11: 579000
B12: Net Plumbing BOQ | E12: =E10-E11 -> 2759206
B14: Total Amount | E14: =E10+E8+E6 -> 6335815.5
E19: =5755861-E14+579955 -> 0.5

Sheet HVAC
A1: DOLMEN CITY FAMILY AREA, SECOND FLOOR | L1: BILL OF QUANTITIES
A2: HVAC WORKS | L2: DATED: APRIL 12, 2023
A4: BILL OF QUANTITIES
A6: (1) | B6: (2) | E6: (3) | F6: (4) | G6: (5) | H6: (6) | I6: (7) | J6: (8) | K6: (9) | L6: (10)
A7: ITEM NO. | B7: DESCRIPTION | E7: ESTIMATED QUANTITY | F7: UNIT | G7: MATERIAL | I7: INSTALLATION | K7: TOTAL
G8: RATE | H8: AMOUNT | I8: RATE | J8: AMOUNT | K8: RATE | L8: AMOUNT
G9: (Rs.) | H9: (Rs.) | I9: (Rs.) | J9: (Rs.) | K9: (Rs.) | L9: (Rs.)
H10: (3) x (5) | J10: (3) x (7) | K10: (5) + (7) | L10: (6) + (8)
A11: 1 | B11: HYDRONIC PIPING & SPECIALITIES (SECTION 23 21 13 & DS/1637-23 21 13)
A12: 1.1 | B12: Drain Piping uPVC Pressure Pipe (IP/1) (Section 23 21 13 & DS/1637-23 21 13)
A13: 1.1.1 | B13: Ø 1" (Ø 25mm) | E13: 12 | F13: Rm | G13: 765 | H13: =G13*E13 -> 9180 | I13: 150 | J13: =I13*E13 -> 1800 | L13: =J13+H13 -> 10980
A14: 1.1.2 | B14: Pipe Sleeves | E14: 1 | F14: Lot | G14: 4000 | H14: =G14*E14 -> 4000 | I14: 1000 | J14: =I14*E14 -> 1000 | L14: =J14+H14 -> 5000
A15: 1.1.3 | B15: Pipe Supports (Section 23 05 29) | E15: 1 | F15: Lot | G15: 18000 | H15: =G15*E15 -> 18000 | I15: 2000 | J15: =I15*E15 -> 2000 | L15: =J15+H15 -> 20000
A16: Sub-total Carried to Summary
A17: 2 | B17: DUCT WORK (MACHINE MADE) (SECTION 23 31 13)
A18: 2.1 | B18: Sheet Metal Duct Work (Air Conditioning) (Supply Air), Machine made Ducts (Section 23 31 13) | E18: 74 | F18: m2 | G18: 4900 | H18: =G18*E18 -> 362600 | I18: 900 | J18: =I18*E18 -> 66600 | L18: =J18+H18 -> 429200
A19: 2.2 | B19: Sheet Metal Duct Work (Air Conditioning) (Return Air), Machine made Ducts (Section 23 31 13) | E19: 5.6 | F19: m2 | G19: 4900 | H19: =G19*E19 -> 27440 | I19: 900 | J19: =I19*E19 -> 5040 | L19: =J19+H19 -> 32480
A20: 2.3 | B20: Sheet Metal Duct Work (Exhaust Air) Machine made Ducts (Section 23 31 13) | E20: 12.1 | F20: m2 | G20: 4900 | H20: =G20*E20 -> 59290 | I20: 900 | J20: =I20*E20 -> 10890 | L20: =J20+H20 -> 70180
A21: 2.4 | B21: Inspection and Insulation Replacement of Existing AHU C2-12 Supply Duct | E21: 1 | F21: Lot | G21: 72000 | H21: =G21*E21 -> 72000 | I21: 12000 | J21: =I21*E21 -> 12000 | L21: =J21+H21 -> 84000
A22: 2.5 | B22: Volume Control Damper | E22: 1 | F22: Lot | G22: 48500 | H22: =G22*E22 -> 48500 | I22: 7000 | J22: =I22*E22 -> 7000 | L22: =J22+H22 -> 55500
A23: 2.6 | B23: Duct Test Holes | E23: 1 | F23: Lot | H23: =G23*E23 -> 0 | J23: =I23*E23 -> 0 | L23: =J23+H23 -> 0
A24: 2.7 | B24: Duct Supports (Hot Dipped Galvanized up to 50 to 70 Micron) System | E24: 1 | F24: Lot | G24: 45000 | H24: =G24*E24 -> 45000 | I24: 15000 | J24: =I24*E24 -> 15000 | L24: =J24+H24 -> 60000
A25: 2.8 | B25: G.I Frame as Duct Sleeves | E25: 1 | F25: Lot | G25: 11000 | H25: =G25*E25 -> 11000 | I25: 2000 | J25: =I25*E25 -> 2000 | L25: =J25+H25 -> 13000
A26: Sub-total Carried to Summary
A27: 3 | B27: SOUND LINERS ON SUPPLY AND RETURN AIR DUCTS (SECTION 23 33 19)
A28: 3.1 | B28: Supply Air Duct (32"x18") | E28: 2.5 | F28: Rm | G28: 7500 | H28: =G28*E28 -> 18750 | I28: 1000 | J28: =I28*E28 -> 2500 | L28: =J28+H28 -> 21250
A29: 3.2 | B29: Return Air Duct (14"x12") | E29: 2.05 | F29: Rm | G29: 5190 | H29: =G29*E29 -> 10639.5 | I29: 1000 | J29: =I29*E29 -> 2050 | L29: =J29+H29 -> 12689.5
A30: Sub-total Carried to Summary
A31: 4 | B31: THERMAL INSULATION (SECTION 23 07 13 & 23 07 19)
A32: 4.1 | B32: Sheet Metal Duct Work (Air-Conditioning) (Supply Air, Return Air & Fresh Air) | E32: =E18+E19 -> 79.6 | F32: m2 | G32: 6750 | H32: =G32*E32 -> 537300 | I32: 700 | J32: =I32*E32 -> 55720 | L32: =J32+H32 -> 593020
A33: 4.2 | B33: Sheet Metal Duct Work (Exhaust Air) | E33: =E20 -> 12.1 | F33: m2 | G33: 5900 | H33: =G33*E33 -> 71390 | I33: 600 | J33: =I33*E33 -> 7260 | L33: =J33+H33 -> 78650
A34: Sub-total Carried to Summary
A35: 5 | B35: AIR DEVICES (SECTION 23 37 13)
A36: 5.1 | B36: Supply & Installation of Tuttle & Bailey Supply Air Linear Slot Diffuser (Series 6000)
A37: 5.1.1 | B37: Air Terminal Number (ST-01) | E37: 1 | F37: No. | G37: 3200 | H37: =G37*E37 -> 3200 | I37: 1000 | J37: =I37*E37 -> 1000 | L37: =J37+H37 -> 4200
A38: 5.1.2 | B38: Air Terminal Number (ST-02) | E38: 1 | F38: No. | G38: 3200 | H38: =G38*E38 -> 3200 | I38: 1000 | J38: =I38*E38 -> 1000 | L38: =J38+H38 -> 4200
A39: 5.1.3 | B39: Air Terminal Number (ST-03) | E39: 1 | F39: No. | G39: 4700 | H39: =G39*E39 -> 4700 | I39: 1000 | J39: =I39*E39 -> 1000 | L39: =J39+H39 -> 5700
A40: 5.1.4 | B40: Air Terminal Number (ST-04) | E40: 1 | F40: No. | G40: 5880 | H40: =G40*E40 -> 5880 | I40: 1000 | J40: =I40*E40 -> 1000 | L40: =J40+H40 -> 6880
A41: 5.1.5 | B41: Air Terminal Number (ST-05) | E41: 1 | F41: No. | G41: 3300 | H41: =G41*E41 -> 3300 | I41: 1000 | J41: =I41*E41 -> 1000 | L41: =J41+H41 -> 4300
A42: 5.1.6 | B42: Air Terminal Number (ST-06) | E42: 3 | F42: Nos. | G42: 5880 | H42: =G42*E42 -> 17640 | I42: 1000 | J42: =I42*E42 -> 3000 | L42: =J42+H42 -> 20640
...

Sheet Plumbing
A1: DOLMEN CITY FAMILY AREA, SECOND FLOOR | K1: BILL OF QUANTITES
A2: PLUMBING WORKS | K2: DATED: APRIL 12, 2023
A4: BILL OF QUANTITES
A6: (1) | B6: (2) | D6: (3) | E6: (4) | F6: (5) | G6: (6) | H6: (7) | I6: (8) | J6: (9) | K6: (10)
A7: ITEM NO. | B7: DESCRIPTION | D7: ESTIMATED QUANTITY | E7: UNIT | F7: MATERIAL | H7: INSTALLATION | J7: TOTAL
F8: RATE | G8: AMOUNT | H8: RATE | I8: AMOUNT | J8: RATE | K8: AMOUNT
F9: (Rs.) | G9: (Rs.) | H9: (Rs.) | I9: (Rs.) | J9: (Rs.) | K9: (Rs.)
G10: (3) x (5) | I10: (3) x (7) | J10: (5) + (7) | K10: (6) + (8)
A11: 1 | B11: COLD WATER SUPPLY SYSTEM (DOMESTIC WATER)
A12: 1.1 | B12: Poly Propylene Random Pipes - PPR Pipe PN-20 Including all Fittings and Accessories Required for Piping Installation, Testing & Commissioning (Section 22 11 16 & DS/1283E-22 11 16)
A13: 1.1.1 | B13: Ø 65mm | D13: - | E13: Rm | G13: Rate Only | I13: Rate Only | K13: Rate Only
A14: 1.1.2 | B14: Ø 50mm | D14: 7.5 | E14: Rm | F14: 6500 | G14: =F14*D14 -> 48750 | H14: 500 | I14: =H14*D14 -> 3750 | K14: =I14+G14 -> 52500
A15: 1.1.3 | B15: Ø 40mm | D15: 4 | E15: Rm | F15: 4500 | G15: =F15*D15 -> 18000 | H15: 450 | I15: =H15*D15 -> 1800 | K15: =I15+G15 -> 19800
A16: 1.1.4 | B16: Ø 32mm | D16: 13 | E16: Rm | F16: 2450 | G16: =F16*D16 -> 31850 | H16: 400 | I16: =H16*D16 -> 5200 | K16: =I16+G16 -> 37050
A17: 1.1.5 | B17: Ø 25mm | D17: 25 | E17: Rm | F17: 1900 | G17: =F17*D17 -> 47500 | H17: 350 | I17: =H17*D17 -> 8750 | K17: =I17+G17 -> 56250
A18: 1.1.6 | B18: Ø 20mm | D18: 3 | E18: Rm | F18: 1200 | G18: =F18*D18 -> 3600 | H18: 300 | I18: =H18*D18 -> 900 | K18: =I18+G18 -> 4500
A19: 1.2 | B19: Valve & Specialities
A20: 1.2.1 | B20: Gate Valves - Brass (Including all Fittings and Accessories Required for Valve Installation) (Section 22 05 23)
A21: 1.2.1.1 | B21: Ø 50mm | D21: - | E21: Nos. | G21: Rate Only | I21: Rate Only | K21: Rate Only
A22: 1.2.1.2 | B22: Ø 40mm | D22: - | E22: Nos. | G22: Rate Only | I22: Rate Only | K22: Rate Only
A23: 1.2.1.3 | B23: Ø 32mm | D23: 3 | E23: Nos. | F23: 11250 | G23: =F23*D23 -> 33750 | H23: 1000 | I23: =H23*D23 -> 3000 | K23: =I23+G23 -> 36750
A24: 1.2.1.4 | B24: Ø 25mm | D24: 6 | E24: Nos. | F24: 8500 | G24: =F24*D24 -> 51000 | H24: 1000 | I24: =H24*D24 -> 6000 | K24: =I24+G24 -> 57000
A25: 1.2.2 | B25: Air Vents (Including all Fittings and Accessories Required for Air Vent Installation. Refer Detail # FND/PH/07) (Section 22 68 35)
A26: 1.2.2.1 | B26: Ø 25mm | D26: 1 | E26: Nos. | F26: 9000 | G26: =F26*D26 -> 9000 | H26: 1000 | I26: =H26*D26 -> 1000 | K26: =I26+G26 -> 10000
A27: 1.2.3 | B27: Pressure Reducing Valves (PRV Assembly with Complete Accessories e.g Valves, Strainers, Pressure Gauges etc.) Refer Tender Drawings (Section 22 05 23)
A28: 1.2.3.1 | B28: Ø 50mm | D28: 1 | E28: No. | F28: 148000 | G28: =F28*D28 -> 148000 | H28: 3000 | I28: =H28*D28 -> 3000 | K28: =I28+G28 -> 151000
A29: 1.3 | B29: Engineered Pipe Support System as per make indicated in Approved list of Manufacturers in Tender document. | D29: 1 | E29: Lot | F29: 45000 | G29: =F29*D29 -> 45000 | H29: 8000 | I29: =H29*D29 -> 8000 | K29: =I29+G29 -> 53000
A30: 1.4 | B30: Pressure Testing of Water Supply Piping (Minimum 150 psi) including all equipment, accessories and arrangements required for Pressure Testing | D30: 1 | E30: Lot | F30: 0 | G30: =F30*D30 -> 0 | H30: 25000 | I30: =H30*D30 -> 25000 | K30: =I30+G30 -> 25000
A31: 1.5 | B31: Supply & Installation of Access Panel 300mm x 300mm in False Ceiling as shown in Tender Drawings | D31: 5 | E31: Nos. | F31: 9000 | G31: =F31*D31 -> 45000 | H31: 1000 | I31: =H31*D31 -> 5000 | K31: =I31+G31 -> 50000
A32: 1.6 | B32: Supply & Installation of Access Panel 600mm x 600mm in False Ceiling as shown in Tender Drawings | D32: 1 | E32: No. | F32: 18000 | G32: =F32*D32 -> 18000 | H32: 1000 | I32: =H32*D32 -> 1000 | K32: =I32+G32 -> 19000
A33: 1.7 | B33: Pressure Gauge With Siphon and Gauge Cock (Section 22 05 23) | D33: 1 | E33: No. | F33: 10000 | G33: =F33*D33 -> 10000 | H33: 1000 | I33: =H33*D33 -> 1000 | K33: =I33+G33 -> 11000
A34: Sub-total Carried to Summary
A35: 2 | B35: HOT & TEMPERED WATER SUPPLY SYSTEM (DOMESTIC WATER)
A36: 2.1 | B36: Poly Propylene Random Pipes - PPR Pipe PN-20 Including all Fittings and Accessories Required for Piping Installation, Testing & Commissioning (Section 22 11 16 & DS/1283E-22 11 16)
A37: 2.1.1 | B37: Ø 32mm | D37: - | E37: Rm | G37: Rate Only | I37: Rate Only | K37: Rate Only
A38: 2.1.2 | B38: Ø 25mm | D38: 32 | E38: Rm | F38: 1650 | G38: =F38*D38 -> 52800 | H38: 400 | I38: =H38*D38 -> 12800 | K38: =I38+G38 -> 65600
A39: 2.1.3 | B39: Ø 20mm | D39: - | E39: Rm | G39: Rate Only | I39: Rate Only | K39: Rate Only
A40: 2.2 | B40: Valve & Specialities
A41: 2.2.1 | B41: 3 Way Thermostatic Mixing Valve (Including all Fittings and Accessories Required for Valve Installation)
A42: 2.2.1.1 | B42: Ø 25mm | D42: 2 | E42: Nos. | F42: 86000 | G42: =F42*D42 -> 172000 | H42: 2000 | I42: =H42*D42 -> 4000 | K42: =I42+G42 -> 176000
...

Sheet Fire
A1: DOLMEN CITY FAMILY AREA, SECOND FLOOR | J1: BILL OF QUANTITIES
A2: FIRE SUPPRESSION SYSTEM WORKS | J2: DATED: APRIL 12, 2023
A4: BILL OF QUANTITIES
A6: (1) | B6: (2) | C6: (3) | D6: (4) | E6: (5) | F6: (6) | G6: (7) | H6: (8) | I6: (9) | J6: (10)
A7: ITEM NO. | B7: DESCRIPTION | C7: ESTIMATED QUANTITY | D7: UNIT | E7: MATERIAL | G7: INSTALLATION | I7: TOTAL
E8: RATE | F8: AMOUNT | G8: RATE | H8: AMOUNT | I8: RATE | J8: AMOUNT
E9: (Rs.) | F9: (Rs.) | G9: (Rs.) | H9: (Rs.) | I9: (Rs.) | J9: (Rs.)
F10: (3) x (5) | H10: (3) x (7) | I10: (5) + (7) | J10: (6) + (8)
A11: 1 | B11: FIRE SPRINKLERS (SECTION 21 13 10 & DS/1283E-21 13 10)
A12: 1.1 | B12: Fire Sprinkler-Concealed Pendent, Standard Response (SP-01)- NEW | C12: 5 | D12: Nos. | E12: 9000 | F12: =E12*C12 -> 45000 | G12: 1000 | H12: =G12*C12 -> 5000 | J12: =H12+F12 -> 50000
A13: 1.2 | B13: Dismantling and relocation of Existing Fire Sprinkler-Concealed Pendent, Standard Response (SP-01)- Complete in all Respect | C13: 1 | D13: Lot | E13: 0 | F13: =E13*C13 -> 0 | G13: 35000 | H13: =G13*C13 -> 35000 | J13: =H13+F13 -> 35000
A14: 1.3 | B14: Cabinet complete with 06 Spare Sprinklers (Pendent ESFR Sprinkler) (SP-01) | C14: - | D14: No. | F14: Rate Only | H14: Rate Only | J14: Rate Only
A15: Sub-total Carried to Summary
A16: 2 | B16: CORRUGATED STAINLESS STEEL FLEXIBLE CONNECTOR
A17: 2.1 | B17: Corrugated Stainless Steel Flexible Connector Ø 1" X 3 ft (UL/FM) - NEW | C17: =C12 -> 5 | D17: Nos. | E17: 11000 | F17: =E17*C17 -> 55000 | G17: 1000 | H17: =G17*C17 -> 5000 | J17: =H17+F17 -> 60000
A18: Sub-total Carried to Summary
A19: 3 | B19: PORTABLE FIRE EXTINGUISHER FOR FIRE TYPES A, B, C & AFFF (SECTION 21 21 10 & DS/1283E-21 21 10)
A20: 3.1 | B20: Supply & Installation of 6kg Dry Powder Extinguisher (ABC) | C20: 1 | D20: No. | E20: 17000 | F20: =E20*C20 -> 17000 | G20: 500 | H20: =G20*C20 -> 500 | J20: =H20+F20 -> 17500
A21: Sub-total Carried to Summary
A22: 4 | B22: BLACK STEEL SCHEDULE-40 PIPING (SECTION 21 10 10)
A23: 4.1 | B23: Welded Piping System
A24: 4.1.1 | B24: Ø 250 mm | C24: - | D24: Rm | F24: Rate Only | H24: Rate Only | J24: Rate Only
A25: 4.1.2 | B25: Ø 200 mm | C25: - | D25: Rm | F25: Rate Only | H25: Rate Only | J25: Rate Only
A26: 4.1.3 | B26: Ø 150 mm | C26: - | D26: Rm | F26: Rate Only | H26: Rate Only | J26: Rate Only
A27: 4.1.4 | B27: Ø 100 mm | C27: - | D27: Rm | F27: Rate Only | H27: Rate Only | J27: Rate Only
A28: 4.1.5 | B28: Ø 75 mm | C28: - | D28: Rm | F28: Rate Only | H28: Rate Only | J28: Rate Only
A29: 4.1.6 | B29: Ø 65 mm | C29: - | D29: Rm | F29: Rate Only | H29: Rate Only | J29: Rate Only
A30: 4.2 | B30: Threaded Piping System
A31: 4.2.1 | B31: Ø 50 mm | C31: - | D31: Rm | E31: 6800 | F31: Rate Only | G31: 1200 | H31: Rate Only | J31: Rate Only
A32: 4.2.2 | B32: Ø 40 mm | C32: 4 | D32: Rm | E32: 5750 | F32: =E32*C32 -> 23000 | G32: 1000 | H32: =G32*C32 -> 4000 | J32: =H32+F32 -> 27000
A33: 4.2.3 | B33: Ø 32 mm | C33: 7 | D33: Rm | E33: 4800 | F33: =E33*C33 -> 33600 | G33: 900 | H33: =G33*C33 -> 6300 | J33: =H33+F33 -> 39900
A34: 4.2.4 | B34: Ø 25 mm | C34: 44 | D34: Rm | E34: 3250 | F34: =E34*C34 -> 143000 | G34: 800 | H34: =G34*C34 -> 35200 | J34: =H34+F34 -> 178200
A35: Sub-total Carried to Summary
A36: 5 | B36: SIESMIC BRACING
A37: 5.1 | B37: Transverse Seismic Bracing (As per FND Detail No. FND/SS/10)
A38: 5.1.1 | B38: Ø 200 mm | C38: - | D38: No. | F38: Rate Only | H38: Rate Only | J38: Rate Only
A39: 5.1.2 | B39: Ø 150 mm | C39: - | D39: No. | F39: Rate Only | H39: Rate Only | J39: Rate Only
A40: 5.1.3 | B40: Ø 100 mm | C40: - | D40: No. | F40: Rate Only | H40: Rate Only | J40: Rate Only
A41: 5.1.4 | B41: Ø 75 mm | C41: - | D41: No. | F41: Rate Only | H41: Rate Only | J41: Rate Only
A42: 5.1.5 | B42: Ø 65 mm | C42: - | D42: No. | F42: Rate Only | H42: Rate Only | J42: Rate Only
...
